<?xml version="1.0" ?>
<!-- =================================================================================== -->
<!-- |    This document was autogenerated by xacro from summit_xl_gen_std.urdf.xacro   | -->
<!-- |    EDITING THIS FILE BY HAND IS NOT RECOMMENDED                                 | -->
<!-- =================================================================================== -->
<robot name="summit_xl">
  <!-- *************** -->
  <!-- Robots Elements -->
  <!-- *************** -->
  <!-- Here we create the robot elements using the xacro:macros imported at the beggining of this file -->
  <link name="robot_base_footprint">
    <visual>
      <origin rpy="0 0 0" xyz="0 0 0"/>
      <geometry>
        <box size="0.001 0.001 0.001"/>
      </geometry>
    </visual>
  </link>
  <joint name="robot_base_footprint_joint" type="fixed">
    <origin rpy="0 0 0" xyz="0 0 0.11"/>
    <!-- ${wheel_radius} property must be defined inside wheel description -->
    <parent link="robot_base_footprint"/>
    <child link="robot_base_link"/>
  </joint>
  <!-- BASE_LINK -->
  <link name="robot_base_link">
    <inertial>
      <mass value="25.0"/>
      <origin xyz="0 0 0"/>
      <inertia ixx="1.391" ixy="0.004" ixz="0.0" iyy="6.853" iyz="0.0" izz="6.125"/>
    </inertial>
    <visual>
      <origin rpy="0 0 0" xyz="0 0 0"/>
      <geometry>
        <mesh filename="summit_xl_chassis.dae"/>
      </geometry>
      <material name="darkgrey">
        <color rgba="0.1 0.1 0.1 1"/>
      </material>
    </visual>
    <collision>
      <origin rpy="0 0 0 " xyz="0 0 0"/>
      <geometry>
        <mesh filename="summit_xl_chassis_collision.dae"/>
      </geometry>
    </collision>
  </link>
  <!-- DOCKING CONTACTS -->
  <joint name="robot_base_docking_joint" type="fixed">
    <origin rpy="0 0 0 " xyz="0.284 0.012 0.068"/>
    <parent link="robot_base_link"/>
    <child link="robot_base_docking_contact_link"/>
  </joint>
  <!-- DOCKING LINK -->
  <link name="robot_base_docking_contact_link"/>
  <!--WHEEL TIRE -->
  <joint name="robot_front_right_wheel_joint" type="revolute">
    <parent link="robot_base_link"/>
    <child link="robot_front_right_wheel"/>
    <origin rpy="0 0 0" xyz="0.229 -0.235 0.0"/>
    <axis rpy="0 0 0" xyz="0 1 0"/>
    <limit effort="100" velocity="100" lower="-1000000" upper="1000000"/>
    <joint_properties damping="0.0" friction="0.0"/>
  </joint>
  <link name="robot_front_right_wheel">
    <visual>
      <origin rpy="0 0 0" xyz="0 0 0"/>
      <geometry>
        <mesh filename="rubber_wheel_right.dae"/>
      </geometry>
    </visual>
    <collision>
      <origin rpy="1.5707963267948966 0 0" xyz="0 0 0"/>
      <geometry>
        <cylinder length="0.15" radius="0.11"/>
      </geometry>
    </collision>
    <inertial>
      <mass value="6.5"/>
      <origin xyz="0 0 0"/>
      <inertia ixx="0.031849999999999996" ixy="0" ixz="0" iyy="0.039325" iyz="0" izz="0.031849999999999996"/>
    </inertial>
  </link>
  <!--WHEEL TIRE -->
  <joint name="robot_front_left_wheel_joint" type="revolute">
    <parent link="robot_base_link"/>
    <child link="robot_front_left_wheel"/>
    <origin rpy="0 0 0" xyz="0.229 0.235 0.0"/>
    <axis rpy="0 0 0" xyz="0 1 0"/>
    <limit effort="100" velocity="100" lower="-1000000" upper="1000000"/>
    <joint_properties damping="0.0" friction="0.0"/>
  </joint>
  <link name="robot_front_left_wheel">
    <visual>
      <origin rpy="0 0 0" xyz="0 0 0"/>
      <geometry>
        <mesh filename="rubber_wheel_left.dae"/>
      </geometry>
    </visual>
    <collision>
      <origin rpy="1.5707963267948966 0 0" xyz="0 0 0"/>
      <geometry>
        <cylinder length="0.15" radius="0.11"/>
      </geometry>
    </collision>
    <inertial>
      <mass value="6.5"/>
      <origin xyz="0 0 0"/>
      <inertia ixx="0.031849999999999996" ixy="0" ixz="0" iyy="0.039325" iyz="0" izz="0.031849999999999996"/>
    </inertial>
  </link>
  <!--WHEEL TIRE -->
  <joint name="robot_back_left_wheel_joint" type="revolute">
    <parent link="robot_base_link"/>
    <child link="robot_back_left_wheel"/>
    <origin rpy="0 0 0" xyz="-0.229 0.235 0.0"/>
    <axis rpy="0 0 0" xyz="0 1 0"/>
    <limit effort="100" velocity="100" lower="-1000000" upper="1000000"/>
    <joint_properties damping="0.0" friction="0.0"/>
  </joint>
  <link name="robot_back_left_wheel">
    <visual>
      <origin rpy="0 0 0" xyz="0 0 0"/>
      <geometry>
        <mesh filename="rubber_wheel_left.dae"/>
      </geometry>
    </visual>
    <collision>
      <origin rpy="1.5707963267948966 0 0" xyz="0 0 0"/>
      <geometry>
        <cylinder length="0.15" radius="0.11"/>
      </geometry>
    </collision>
    <inertial>
      <mass value="6.5"/>
      <origin xyz="0 0 0"/>
      <inertia ixx="0.031849999999999996" ixy="0" ixz="0" iyy="0.039325" iyz="0" izz="0.031849999999999996"/>
    </inertial>
  </link>
  <!--WHEEL TIRE -->
  <joint name="robot_back_right_wheel_joint" type="revolute">
    <parent link="robot_base_link"/>
    <child link="robot_back_right_wheel"/>
    <origin rpy="0 0 0" xyz="-0.229 -0.235 0.0"/>
    <axis rpy="0 0 0" xyz="0 1 0"/>
    <limit effort="100" velocity="100" lower="-1000000" upper="1000000"/>
    <joint_properties damping="0.0" friction="0.0"/>
  </joint>
  <link name="robot_back_right_wheel">
    <visual>
      <origin rpy="0 0 0" xyz="0 0 0"/>
      <geometry>
        <mesh filename="rubber_wheel_right.dae"/>
      </geometry>
    </visual>
    <collision>
      <origin rpy="1.5707963267948966 0 0" xyz="0 0 0"/>
      <geometry>
        <cylinder length="0.15" radius="0.11"/>
      </geometry>
    </collision>
    <inertial>
      <mass value="6.5"/>
      <origin xyz="0 0 0"/>
      <inertia ixx="0.031849999999999996" ixy="0" ixz="0" iyy="0.039325" iyz="0" izz="0.031849999999999996"/>
    </inertial>
  </link>
  <joint name="robot_imu_joint" type="fixed">
    <axis xyz="1 0 0"/>
    <!--origin xyz="0 0 0.2825"/-->
    <origin rpy="0 0 0" xyz="-0.18 0.0 0.170"/>
    <parent link="robot_base_link"/>
    <child link="robot_imu_link"/>
  </joint>
  <link name="robot_imu_link">
    <inertial>
      <origin rpy="0 0 0" xyz="0.0 0 0.01"/>
      <mass value="0.005"/>
      <inertia ixx="8.333333333333334e-10" ixy="0" ixz="0" iyy="8.333333333333334e-10" iyz="0" izz="8.333333333333334e-10"/>
    </inertial>
    <visual>
      <origin rpy="0 0 0" xyz="0 0 0"/>
      <geometry>
        <box size="0.001 0.001 0.001"/>
      </geometry>
    </visual>
    <!--collision>
	        <origin rpy="0 0 0" xyz="0 0 0"/>
	        <geometry>
	          <box size="0.001 0.001 0.001"/>
	        </geometry>
	      </collision-->
  </link>
</robot>

