<?xml version="1.0" ?>
<!-- =================================================================================== -->
<!-- |    This document was autogenerated by xacro from summit_xl_gen_std.urdf.xacro   | -->
<!-- |    EDITING THIS FILE BY HAND IS NOT RECOMMENDED                                 | -->
<!-- =================================================================================== -->
<robot name="summit_xl">
  <!-- *************** -->
  <!-- Robots Elements -->
  <!-- *************** -->
  <!-- Here we create the robot elements using the xacro:macros imported at the beggining of this file -->
  <link name="robot_base_footprint">
    <visual>
      <origin rpy="0 0 0" xyz="0 0 0"/>
      <geometry>
        <box size="0.001 0.001 0.001"/>
      </geometry>
    </visual>
  </link>
  <joint name="robot_base_footprint_joint" type="fixed">
    <origin rpy="0 0 0" xyz="0 0 0.11"/>
    <!-- ${wheel_radius} property must be defined inside wheel description -->
    <parent link="robot_base_footprint"/>
    <child link="robot_base_link"/>
  </joint>
  <!-- BASE_LINK -->
  <link name="robot_base_link">
    <inertial>
      <mass value="25.0"/>
      <origin xyz="0 0 0"/>
      <inertia ixx="1.391" ixy="0.004" ixz="0.0" iyy="6.853" iyz="0.0" izz="6.125"/>
    </inertial>
    <visual>
      <origin rpy="0 0 0" xyz="0 0 0"/>
      <geometry>
        <mesh filename="summit_xl_chassis.dae"/>
      </geometry>
      <material name="darkgrey">
        <color rgba="0.1 0.1 0.1 1"/>
      </material>
    </visual>
    <collision>
      <origin rpy="0 0 0 " xyz="0 0 0"/>
      <geometry>
        <mesh filename="summit_xl_chassis_collision.dae"/>
      </geometry>
    </collision>
  </link>
  <!-- DOCKING CONTACTS -->
  <joint name="robot_base_docking_joint" type="fixed">
    <origin rpy="0 0 0 " xyz="0.284 0.012 0.068"/>
    <parent link="robot_base_link"/>
    <child link="robot_base_docking_contact_link"/>
  </joint>
  <!-- DOCKING LINK -->
  <link name="robot_base_docking_contact_link"/>
  <!--WHEEL TIRE -->
  <joint name="robot_front_right_wheel_joint" type="revolute">
    <parent link="robot_base_link"/>
    <child link="robot_front_right_wheel"/>
    <origin rpy="0 0 0" xyz="0.229 -0.235 0.0"/>
    <axis rpy="0 0 0" xyz="0 1 0"/>
    <limit effort="100" velocity="100" lower="-1000000" upper="1000000"/>
    <joint_properties damping="0.0" friction="0.0"/>
  </joint>
  <link name="robot_front_right_wheel">
    <visual>
      <origin rpy="0 0 0" xyz="0 0 0"/>
      <geometry>
        <mesh filename="rubber_wheel_right.dae"/>
      </geometry>
    </visual>
    <collision>
      <origin rpy="1.5707963267948966 0 0" xyz="0 0 0"/>
      <geometry>
        <cylinder length="0.15" radius="0.11"/>
      </geometry>
    </collision>
    <inertial>
      <mass value="6.5"/>
      <origin xyz="0 0 0"/>
      <inertia ixx="0.031849999999999996" ixy="0" ixz="0" iyy="0.039325" iyz="0" izz="0.031849999999999996"/>
    </inertial>
  </link>
  <!--WHEEL TIRE -->
  <joint name="robot_front_left_wheel_joint" type="revolute">
    <parent link="robot_base_link"/>
    <child link="robot_front_left_wheel"/>
    <origin rpy="0 0 0" xyz="0.229 0.235 0.0"/>
    <axis rpy="0 0 0" xyz="0 1 0"/>
    <limit effort="100" velocity="100" lower="-1000000" upper="1000000"/>
    <joint_properties damping="0.0" friction="0.0"/>
  </joint>
  <link name="robot_front_left_wheel">
    <visual>
      <origin rpy="0 0 0" xyz="0 0 0"/>
      <geometry>
        <mesh filename="rubber_wheel_left.dae"/>
      </geometry>
    </visual>
    <collision>
      <origin rpy="1.5707963267948966 0 0" xyz="0 0 0"/>
      <geometry>
        <cylinder length="0.15" radius="0.11"/>
      </geometry>
    </collision>
    <inertial>
      <mass value="6.5"/>
      <origin xyz="0 0 0"/>
      <inertia ixx="0.031849999999999996" ixy="0" ixz="0" iyy="0.039325" iyz="0" izz="0.031849999999999996"/>
    </inertial>
  </link>
  <!--WHEEL TIRE -->
  <joint name="robot_back_left_wheel_joint" type="revolute">
    <parent link="robot_base_link"/>
    <child link="robot_back_left_wheel"/>
    <origin rpy="0 0 0" xyz="-0.229 0.235 0.0"/>
    <axis rpy="0 0 0" xyz="0 1 0"/>
    <limit effort="100" velocity="100" lower="-1000000" upper="1000000"/>
    <joint_properties damping="0.0" friction="0.0"/>
  </joint>
  <link name="robot_back_left_wheel">
    <visual>
      <origin rpy="0 0 0" xyz="0 0 0"/>
      <geometry>
        <mesh filename="rubber_wheel_left.dae"/>
      </geometry>
    </visual>
    <collision>
      <origin rpy="1.5707963267948966 0 0" xyz="0 0 0"/>
      <geometry>
        <cylinder length="0.15" radius="0.11"/>
      </geometry>
    </collision>
    <inertial>
      <mass value="6.5"/>
      <origin xyz="0 0 0"/>
      <inertia ixx="0.031849999999999996" ixy="0" ixz="0" iyy="0.039325" iyz="0" izz="0.031849999999999996"/>
    </inertial>
  </link>
  <!--WHEEL TIRE -->
  <joint name="robot_back_right_wheel_joint" type="revolute">
    <parent link="robot_base_link"/>
    <child link="robot_back_right_wheel"/>
    <origin rpy="0 0 0" xyz="-0.229 -0.235 0.0"/>
    <axis rpy="0 0 0" xyz="0 1 0"/>
    <limit effort="100" velocity="100" lower="-1000000" upper="1000000"/>
    <joint_properties damping="0.0" friction="0.0"/>
  </joint>
  <link name="robot_back_right_wheel">
    <visual>
      <origin rpy="0 0 0" xyz="0 0 0"/>
      <geometry>
        <mesh filename="rubber_wheel_right.dae"/>
      </geometry>
    </visual>
    <collision>
      <origin rpy="1.5707963267948966 0 0" xyz="0 0 0"/>
      <geometry>
        <cylinder length="0.15" radius="0.11"/>
      </geometry>
    </collision>
    <inertial>
      <mass value="6.5"/>
      <origin xyz="0 0 0"/>
      <inertia ixx="0.031849999999999996" ixy="0" ixz="0" iyy="0.039325" iyz="0" izz="0.031849999999999996"/>
    </inertial>
  </link>
  <joint name="robot_imu_joint" type="fixed">
    <axis xyz="1 0 0"/>
    <!--origin xyz="0 0 0.2825"/-->
    <origin rpy="0 0 0" xyz="-0.18 0.0 0.170"/>
    <parent link="robot_base_link"/>
    <child link="robot_imu_link"/>
  </joint>
  <link name="robot_imu_link">
    <inertial>
      <origin rpy="0 0 0" xyz="0.0 0 0.01"/>
      <mass value="0.005"/>
      <inertia ixx="8.333333333333334e-10" ixy="0" ixz="0" iyy="8.333333333333334e-10" iyz="0" izz="8.333333333333334e-10"/>
    </inertial>
    <visual>
      <origin rpy="0 0 0" xyz="0 0 0"/>
      <geometry>
        <box size="0.001 0.001 0.001"/>
      </geometry>
    </visual>
    <!--collision>
	        <origin rpy="0 0 0" xyz="0 0 0"/>
	        <geometry>
	          <box size="0.001 0.001 0.001"/>
	        </geometry>
	      </collision-->
  </link>
  <!-- Instance jaco arm -->
  <joint name="robot_arm_base_joint" type="fixed">
    <origin rpy="0.0 0.0 0.0" xyz="0.204 0.0 0.11"/>
    <parent link="robot_base_link"/>
    <child link="robot_arm_base_link"/>
    <axis xyz="0 0 0"/>
  </joint>
  <link name="robot_arm_base_link"/>
  <link name="robot_j2s7s300_link_base">
    <visual>
      <geometry>
        <mesh filename="base.dae"/>
      </geometry>
      <material name="carbon_fiber">
        <color rgba="0.792156862745098 0.819607843137255 0.933333333333333 1"/>
      </material>
    </visual>
    <collision>
      <geometry>
        <mesh filename="base.dae"/>
      </geometry>
    </collision>
    <inertial>
      <mass value="0.46784"/>
      <origin rpy="0 0 0" xyz="0 0 0.1255"/>
      <inertia ixx="0.000951270861568" ixy="0" ixz="0" iyy="0.000951270861568" iyz="0" izz="0.00037427200000000004"/>
    </inertial>
  </link>
  <joint name="robot_j2s7s300_joint_base" type="fixed">
    <parent link="robot_arm_base_link"/>
    <child link="robot_j2s7s300_link_base"/>
    <axis xyz="0 0 0"/>
    <origin rpy="0 0 0" xyz="0 0 0"/>
    <dynamics damping="0.0" friction="0.0"/>
  </joint>
  <link name="robot_j2s7s300_link_1">
    <visual>
      <geometry>
        <mesh filename="shoulder.dae"/>
      </geometry>
      <material name="carbon_fiber">
        <color rgba="0.792156862745098 0.819607843137255 0.933333333333333 1"/>
      </material>
    </visual>
    <visual>
      <geometry>
        <mesh filename="ring_big.dae"/>
      </geometry>
    </visual>
    <collision>
      <geometry>
        <mesh filename="shoulder.dae"/>
      </geometry>
    </collision>
    <inertial>
      <mass value="0.7477"/>
      <origin xyz="0 -0.002 -0.0605"/>
      <inertia ixx="0.0015203172520400004" ixy="0" ixz="0" iyy="0.0015203172520400004" iyz="0" izz="0.00059816"/>
    </inertial>
  </link>
  <joint name="robot_j2s7s300_joint_1" type="revolute">
    <parent link="robot_j2s7s300_link_base"/>
    <child link="robot_j2s7s300_link_1"/>
    <axis xyz="0 0 1"/>
    <limit effort="40" velocity="0.6283185307179586" lower="-1000000" upper="1000000"/>
    <origin rpy="0 3.141592653589793 0" xyz="0 0 0.15675"/>
    <dynamics damping="0.0" friction="0.0"/>
  </joint>
  <link name="robot_j2s7s300_link_2">
    <visual>
      <geometry>
        <mesh filename="arm_half_1.dae"/>
      </geometry>
      <material name="carbon_fiber">
        <color rgba="0.792156862745098 0.819607843137255 0.933333333333333 1"/>
      </material>
    </visual>
    <visual>
      <geometry>
        <mesh filename="ring_big.dae"/>
      </geometry>
    </visual>
    <collision>
      <geometry>
        <mesh filename="arm_half_1.dae"/>
      </geometry>
    </collision>
    <inertial>
      <mass value="0.8447"/>
      <origin xyz="0 -0.103563213 0"/>
      <inertia ixx="0.00247073761701" ixy="0" ixz="0" iyy="0.000380115" iyz="0" izz="0.00247073761701"/>
    </inertial>
  </link>
  <joint name="robot_j2s7s300_joint_2" type="revolute">
    <parent link="robot_j2s7s300_link_1"/>
    <child link="robot_j2s7s300_link_2"/>
    <axis xyz="0 0 1"/>
    <limit effort="80" lower="0.8203047484373349" upper="5.462880558742252" velocity="0.6283185307179586"/>
    <origin rpy="-1.5707963267948966 0 3.141592653589793" xyz="0 0.0016 -0.11875"/>
    <dynamics damping="0.0" friction="0.0"/>
  </joint>
  <link name="robot_j2s7s300_link_3">
    <visual>
      <geometry>
        <mesh filename="arm_half_2.dae"/>
      </geometry>
      <material name="carbon_fiber">
        <color rgba="0.792156862745098 0.819607843137255 0.933333333333333 1"/>
      </material>
    </visual>
    <visual>
      <geometry>
        <mesh filename="ring_big.dae"/>
      </geometry>
    </visual>
    <collision>
      <geometry>
        <mesh filename="arm_half_2.dae"/>
      </geometry>
    </collision>
    <inertial>
      <mass value="0.8447"/>
      <origin xyz="0 0 -0.1022447445"/>
      <inertia ixx="0.00247073761701" ixy="0" ixz="0" iyy="0.00247073761701" iyz="0" izz="0.000380115"/>
    </inertial>
  </link>
  <joint name="robot_j2s7s300_joint_3" type="revolute">
    <parent link="robot_j2s7s300_link_2"/>
    <child link="robot_j2s7s300_link_3"/>
    <axis xyz="0 0 1"/>
    <limit effort="40" velocity="0.6283185307179586" lower="-1000000" upper="1000000"/>
    <origin rpy="-1.5707963267948966 0 0" xyz="0 -0.205 0"/>
    <dynamics damping="0.0" friction="0.0"/>
  </joint>
  <link name="robot_j2s7s300_link_4">
    <visual>
      <geometry>
        <mesh filename="forearm.dae"/>
      </geometry>
      <material name="carbon_fiber">
        <color rgba="0.792156862745098 0.819607843137255 0.933333333333333 1"/>
      </material>
    </visual>
    <visual>
      <geometry>
        <mesh filename="ring_small.dae"/>
      </geometry>
    </visual>
    <collision>
      <geometry>
        <mesh filename="forearm.dae"/>
      </geometry>
    </collision>
    <inertial>
      <mass value="0.6763"/>
      <origin xyz="0 0.081 -0.0086"/>
      <inertia ixx="0.0014202243190800001" ixy="0" ixz="0" iyy="0.000304335" iyz="0" izz="0.0014202243190800001"/>
    </inertial>
  </link>
  <joint name="robot_j2s7s300_joint_4" type="revolute">
    <parent link="robot_j2s7s300_link_3"/>
    <child link="robot_j2s7s300_link_4"/>
    <axis xyz="0 0 1"/>
    <limit effort="40" lower="0.5235987755982988" upper="5.759586531581287" velocity="0.6283185307179586"/>
    <origin rpy="1.5707963267948966 0 3.141592653589793" xyz="0 0 -0.205"/>
    <dynamics damping="0.0" friction="0.0"/>
  </joint>
  <link name="robot_j2s7s300_link_5">
    <visual>
      <geometry>
        <mesh filename="wrist_spherical_1.dae"/>
      </geometry>
      <material name="carbon_fiber">
        <color rgba="0.792156862745098 0.819607843137255 0.933333333333333 1"/>
      </material>
    </visual>
    <visual>
      <geometry>
        <mesh filename="ring_small.dae"/>
      </geometry>
    </visual>
    <collision>
      <geometry>
        <mesh filename="wrist_spherical_1.dae"/>
      </geometry>
    </collision>
    <inertial>
      <mass value="0.463"/>
      <origin xyz="0 0.0028848942 -0.0541932613"/>
      <inertia ixx="0.0004321316048000001" ixy="0" ixz="0" iyy="0.0004321316048000001" iyz="0" izz="9.260000000000001e-05"/>
    </inertial>
  </link>
  <joint name="robot_j2s7s300_joint_5" type="revolute">
    <parent link="robot_j2s7s300_link_4"/>
    <child link="robot_j2s7s300_link_5"/>
    <axis xyz="0 0 1"/>
    <limit effort="20" velocity="0.8377580409572781" lower="-1000000" upper="1000000"/>
    <origin rpy="-1.5707963267948966 0 3.141592653589793" xyz="0 0.2073 -0.0114"/>
    <dynamics damping="0.0" friction="0.0"/>
  </joint>
  <link name="robot_j2s7s300_link_6">
    <visual>
      <geometry>
        <mesh filename="wrist_spherical_2.dae"/>
      </geometry>
      <material name="carbon_fiber">
        <color rgba="0.792156862745098 0.819607843137255 0.933333333333333 1"/>
      </material>
    </visual>
    <visual>
      <geometry>
        <mesh filename="ring_small.dae"/>
      </geometry>
    </visual>
    <collision>
      <geometry>
        <mesh filename="wrist_spherical_2.dae"/>
      </geometry>
    </collision>
    <inertial>
      <mass value="0.463"/>
      <origin xyz="0 0.0497208855 -0.0028562765"/>
      <inertia ixx="0.0004321316048000001" ixy="0" ixz="0" iyy="9.260000000000001e-05" iyz="0" izz="0.0004321316048000001"/>
    </inertial>
  </link>
  <joint name="robot_j2s7s300_joint_6" type="revolute">
    <parent link="robot_j2s7s300_link_5"/>
    <child link="robot_j2s7s300_link_6"/>
    <axis xyz="0 0 1"/>
    <limit effort="20" lower="1.1344640137963142" upper="5.148721293383272" velocity="0.8377580409572781"/>
    <origin rpy="1.5707963267948966 0 3.141592653589793" xyz="0 0 -0.10375"/>
    <dynamics damping="0.0" friction="0.0"/>
  </joint>
  <link name="robot_j2s7s300_link_7">
    <visual>
      <geometry>
        <mesh filename="hand_3finger.dae"/>
      </geometry>
      <material name="carbon_fiber">
        <color rgba="0.792156862745098 0.819607843137255 0.933333333333333 1"/>
      </material>
    </visual>
    <visual>
      <geometry>
        <mesh filename="ring_small.dae"/>
      </geometry>
    </visual>
    <collision>
      <geometry>
        <mesh filename="hand_3finger.dae"/>
      </geometry>
    </collision>
    <inertial>
      <mass value="0.99"/>
      <origin xyz="0 0 -0.06"/>
      <inertia ixx="0.00034532361869999995" ixy="0" ixz="0" iyy="0.00034532361869999995" iyz="0" izz="0.0005815999999999999"/>
    </inertial>
  </link>
  <joint name="robot_j2s7s300_joint_7" type="revolute">
    <parent link="robot_j2s7s300_link_6"/>
    <child link="robot_j2s7s300_link_7"/>
    <axis xyz="0 0 1"/>
    <limit effort="20" velocity="0.8377580409572781" lower="-1000000" upper="1000000"/>
    <origin rpy="-1.5707963267948966 0 3.141592653589793" xyz="0 0.10375 0"/>
    <dynamics damping="0.0" friction="0.0"/>
  </joint>
  <link name="robot_j2s7s300_end_effector"/>
  <joint name="robot_j2s7s300_joint_end_effector" type="fixed">
    <parent link="robot_j2s7s300_link_7"/>
    <child link="robot_j2s7s300_end_effector"/>
    <axis xyz="0 0 0"/>
    <origin rpy="3.141592653589793 0 1.5707963267948966" xyz="0 0 -0.1600"/>
  </joint>
  <link name="robot_j2s7s300_link_finger_1">
    <visual>
      <geometry>
        <mesh filename="finger_proximal.dae"/>
      </geometry>
      <material name="carbon_fiber">
        <color rgba="0.792156862745098 0.819607843137255 0.933333333333333 1"/>
      </material>
    </visual>
    <collision>
      <geometry>
        <mesh filename="finger_proximal.dae"/>
      </geometry>
    </collision>
    <inertial>
      <mass value="0.01"/>
      <origin xyz="0.022 0 0"/>
      <inertia ixx="7.8999684e-07" ixy="0" ixz="0" iyy="7.8999684e-07" iyz="0" izz="8e-08"/>
    </inertial>
  </link>
  <joint name="robot_j2s7s300_joint_finger_1" type="revolute">
    <parent link="robot_j2s7s300_link_7"/>
    <child link="robot_j2s7s300_link_finger_1"/>
    <axis xyz="0 0 1"/>
    <origin rpy="-1.7047873384941834 0.6476144647144773 1.67317415161155" xyz="0.00279 0.03126 -0.11467"/>
    <limit effort="2" lower="0" upper="1.51" velocity="1"/>
  </joint>
  <link name="robot_j2s7s300_link_finger_tip_1">
    <visual>
      <geometry>
        <mesh filename="finger_distal.dae"/>
      </geometry>
      <material name="carbon_fiber">
        <color rgba="0.792156862745098 0.819607843137255 0.933333333333333 1"/>
      </material>
    </visual>
    <collision>
      <geometry>
        <mesh filename="finger_distal.dae"/>
      </geometry>
    </collision>
    <inertial>
      <mass value="0.01"/>
      <origin xyz="0.022 0 0"/>
      <inertia ixx="7.8999684e-07" ixy="0" ixz="0" iyy="7.8999684e-07" iyz="0" izz="8e-08"/>
    </inertial>
  </link>
  <joint name="robot_j2s7s300_joint_finger_tip_1" type="revolute">
    <parent link="robot_j2s7s300_link_finger_1"/>
    <child link="robot_j2s7s300_link_finger_tip_1"/>
    <axis xyz="0 0 1"/>
    <origin rpy="0 0 0" xyz="0.044 -0.003 0"/>
    <limit effort="2" lower="0" upper="2" velocity="1"/>
  </joint>
  <link name="robot_j2s7s300_link_finger_2">
    <visual>
      <geometry>
        <mesh filename="finger_proximal.dae"/>
      </geometry>
      <material name="carbon_fiber">
        <color rgba="0.792156862745098 0.819607843137255 0.933333333333333 1"/>
      </material>
    </visual>
    <collision>
      <geometry>
        <mesh filename="finger_proximal.dae"/>
      </geometry>
    </collision>
    <inertial>
      <mass value="0.01"/>
      <origin xyz="0.022 0 0"/>
      <inertia ixx="7.8999684e-07" ixy="0" ixz="0" iyy="7.8999684e-07" iyz="0" izz="8e-08"/>
    </inertial>
  </link>
  <joint name="robot_j2s7s300_joint_finger_2" type="revolute">
    <parent link="robot_j2s7s300_link_7"/>
    <child link="robot_j2s7s300_link_finger_2"/>
    <axis xyz="0 0 1"/>
    <origin rpy="-1.570796327 .649262481663582 -1.38614049188413" xyz="0.02226 -0.02707 -0.11482"/>
    <limit effort="2" lower="0" upper="1.51" velocity="1"/>
  </joint>
  <link name="robot_j2s7s300_link_finger_tip_2">
    <visual>
      <geometry>
        <mesh filename="finger_distal.dae"/>
      </geometry>
      <material name="carbon_fiber">
        <color rgba="0.792156862745098 0.819607843137255 0.933333333333333 1"/>
      </material>
    </visual>
    <collision>
      <geometry>
        <mesh filename="finger_distal.dae"/>
      </geometry>
    </collision>
    <inertial>
      <mass value="0.01"/>
      <origin xyz="0.022 0 0"/>
      <inertia ixx="7.8999684e-07" ixy="0" ixz="0" iyy="7.8999684e-07" iyz="0" izz="8e-08"/>
    </inertial>
  </link>
  <joint name="robot_j2s7s300_joint_finger_tip_2" type="revolute">
    <parent link="robot_j2s7s300_link_finger_2"/>
    <child link="robot_j2s7s300_link_finger_tip_2"/>
    <axis xyz="0 0 1"/>
    <origin rpy="0 0 0" xyz="0.044 -0.003 0"/>
    <limit effort="2" lower="0" upper="2" velocity="1"/>
  </joint>
  <link name="robot_j2s7s300_link_finger_3">
    <visual>
      <geometry>
        <mesh filename="finger_proximal.dae"/>
      </geometry>
      <material name="carbon_fiber">
        <color rgba="0.792156862745098 0.819607843137255 0.933333333333333 1"/>
      </material>
    </visual>
    <collision>
      <geometry>
        <mesh filename="finger_proximal.dae"/>
      </geometry>
    </collision>
    <inertial>
      <mass value="0.01"/>
      <origin xyz="0.022 0 0"/>
      <inertia ixx="7.8999684e-07" ixy="0" ixz="0" iyy="7.8999684e-07" iyz="0" izz="8e-08"/>
    </inertial>
  </link>
  <joint name="robot_j2s7s300_joint_finger_3" type="revolute">
    <parent link="robot_j2s7s300_link_7"/>
    <child link="robot_j2s7s300_link_finger_3"/>
    <axis xyz="0 0 1"/>
    <origin rpy="-1.570796327 .649262481663582 -1.75545216211587" xyz="-0.02226 -0.02707 -0.11482"/>
    <limit effort="2" lower="0" upper="1.51" velocity="1"/>
  </joint>
  <link name="robot_j2s7s300_link_finger_tip_3">
    <visual>
      <geometry>
        <mesh filename="finger_distal.dae"/>
      </geometry>
      <material name="carbon_fiber">
        <color rgba="0.792156862745098 0.819607843137255 0.933333333333333 1"/>
      </material>
    </visual>
    <collision>
      <geometry>
        <mesh filename="finger_distal.dae"/>
      </geometry>
    </collision>
    <inertial>
      <mass value="0.01"/>
      <origin xyz="0.022 0 0"/>
      <inertia ixx="7.8999684e-07" ixy="0" ixz="0" iyy="7.8999684e-07" iyz="0" izz="8e-08"/>
    </inertial>
  </link>
  <joint name="robot_j2s7s300_joint_finger_tip_3" type="revolute">
    <parent link="robot_j2s7s300_link_finger_3"/>
    <child link="robot_j2s7s300_link_finger_tip_3"/>
    <axis xyz="0 0 1"/>
    <origin rpy="0 0 0" xyz="0.044 -0.003 0"/>
    <limit effort="2" lower="0" upper="2" velocity="1"/>
  </joint>
</robot>

