<?xml version="1.0" ?>
<!-- =================================================================================== -->
<!-- |    This document was autogenerated by xacro from /home/gergondet/devel-src/catkin_ws/mc_ws/src/hrp4/hrp4_description/urdf/hrp4.xacro | -->
<!-- |    EDITING THIS FILE BY HAND IS NOT RECOMMENDED                                 | -->
<!-- =================================================================================== -->
<!--
   hrp4 URDF model

   FIXME: fill missing data: sole, gripper and sensors
  -->
<robot name="hrp4" xmlns:xacro="http://ros.org/wiki/xacro">
  <link name="body">
    <inertial>
      <origin rpy="0 0 0" xyz="-0.0215609 0.00145914 0.14111505"/>
      <mass value="6.93472"/>
      <inertia ixx="0.05776087" ixy="7.331e-05" ixz="0.0014889" iyy="0.0285208" iyz="-0.00075717" izz="0.05527734"/>
    </inertial>
    <visual>
      <origin rpy="0 0 0" xyz="0 0 0"/>
      <geometry>
        <mesh filename="./meshes/WAIST_LINK.dae"/>
      </geometry>
    </visual>
    <collision>
      <origin rpy="0 0 0" xyz="0 0 0"/>
      <geometry>
        <mesh filename="./meshes/WAIST_LINK.dae"/>
      </geometry>
    </collision>
  </link>
  <link name="R_HIP_Y_LINK">
    <inertial>
      <origin rpy="0 0 0" xyz="-0.01667657 2e-08 0.04993135"/>
      <mass value="1.1356"/>
      <inertia ixx="0.00151524" ixy="-2.8e-07" ixz="-0.00048566" iyy="0.00231285" iyz="-0" izz="0.00149651"/>
    </inertial>
    <visual>
      <origin rpy="0 0 0" xyz="0 0 0"/>
      <geometry>
        <mesh filename="./meshes/HIP_Y.dae"/>
      </geometry>
    </visual>
    <collision>
      <origin rpy="0 0 0" xyz="0 0 0"/>
      <geometry>
        <mesh filename="./meshes/HIP_Y.dae"/>
      </geometry>
    </collision>
  </link>
  <link name="R_HIP_R_LINK">
    <inertial>
      <origin rpy="0 0 0" xyz="-0.00431692 0.00595121 -0.00052352"/>
      <mass value="0.58494148"/>
      <inertia ixx="0.00046475" ixy="-1.508e-05" ixz="-6.5e-07" iyy="0.00029804" iyz="2.39e-06" izz="0.00061763"/>
    </inertial>
    <visual>
      <origin rpy="0 0 0" xyz="0 0 0"/>
      <geometry>
        <mesh filename="./meshes/CHEST_P.dae"/>
      </geometry>
    </visual>
    <collision>
      <origin rpy="0 0 0" xyz="0 0 0"/>
      <geometry>
        <mesh filename="./meshes/CHEST_P.dae"/>
      </geometry>
    </collision>
  </link>
  <link name="R_HIP_P_LINK">
    <inertial>
      <origin rpy="0 0 0" xyz="0.00401404 0.01530275 -0.18851723"/>
      <mass value="2.0648"/>
      <inertia ixx="0.03160432" ixy="-3.38e-06" ixz="0.00063965" iyy="0.03070237" iyz="0.00133966" izz="0.00275655"/>
    </inertial>
    <visual>
      <origin rpy="0 0 0" xyz="0 0 0"/>
      <geometry>
        <mesh filename="./meshes/R_HIP_P.dae"/>
      </geometry>
    </visual>
    <collision>
      <origin rpy="0 0 0" xyz="0 0 0"/>
      <geometry>
        <mesh filename="./meshes/R_HIP_P.dae"/>
      </geometry>
    </collision>
  </link>
  <link name="R_KNEE_P_LINK">
    <inertial>
      <origin rpy="0 0 0" xyz="-0.01122115 -0.00133701 -0.15252868"/>
      <mass value="2.08123"/>
      <inertia ixx="0.01900442" ixy="-4.75e-06" ixz="-0.0014589" iyy="0.01944097" iyz="2.008e-05" izz="0.00189659"/>
    </inertial>
    <visual>
      <origin rpy="0 0 0" xyz="0 0 0"/>
      <geometry>
        <mesh filename="./meshes/R_KNEE_P.dae"/>
      </geometry>
    </visual>
    <collision>
      <origin rpy="0 0 0" xyz="0 0 0"/>
      <geometry>
        <mesh filename="./meshes/R_KNEE_P.dae"/>
      </geometry>
    </collision>
  </link>
  <link name="R_ANKLE_P_LINK">
    <inertial>
      <origin rpy="0 0 0" xyz="-0.00368911 -0.00015844 0.00129883"/>
      <mass value="0.26784726"/>
      <inertia ixx="8.094e-05" ixy="-1.6e-07" ixz="-1.33e-06" iyy="0.00015522" iyz="-7e-08" izz="0.00017313"/>
    </inertial>
    <visual>
      <origin rpy="0 0 0" xyz="0 0 0"/>
      <geometry>
        <mesh filename="./meshes/L_ANKLE_P.dae"/>
      </geometry>
    </visual>
    <collision>
      <origin rpy="0 0 0" xyz="0 0 0"/>
      <geometry>
        <mesh filename="./meshes/L_ANKLE_P.dae"/>
      </geometry>
    </collision>
  </link>
  <link name="R_ANKLE_R_LINK">
    <inertial>
      <origin rpy="0 0 0" xyz="-0.00340792 1e-08 -0.04591586"/>
      <mass value="0.72287828"/>
      <inertia ixx="0.00092215" ixy="0" ixz="0.00011963" iyy="0.00102289" iyz="0" izz="0.00089314"/>
    </inertial>
    <visual>
      <origin rpy="0 0 0" xyz="0 0 0"/>
      <geometry>
        <mesh filename="./meshes/R_ANKLE_R.dae"/>
      </geometry>
    </visual>
    <collision>
      <origin rpy="0 0 0" xyz="0 0 0"/>
      <geometry>
        <mesh filename="./meshes/R_ANKLE_R.dae"/>
      </geometry>
    </collision>
  </link>

  <link name="r_sole">
    <inertial>
      <origin rpy="0 0 0" xyz="0 0 0"/>
      <mass value="0.001"/>
      <inertia ixx="0.00001" ixy="0" ixz="0" iyy="0.00001" iyz="0" izz="0.00001"/>
    </inertial>

   <visual>
      <geometry>
        <box size="0.18 0.1 0.007"/>
      </geometry>
      <origin rpy="0 0 0" xyz="0.0 -0.01 0.0029"/>
    </visual>
   <collision>
     <geometry>
        <box size="0.18 0.1 0.007"/>
      </geometry>
      <origin rpy="0 0 0" xyz="0.0 -0.01 0.0029"/>
    </collision>
    <!--inertial>
      <mass value="1.0"/>
      <mu value="0.5"/>
      <inertia ixx="1.1e-09" ixy="0" ixz="0" iyy="1.1e-09" iyz="0" izz="1.1e-09"/>
    </inertial-->

  </link>
<!--
  <link name="r_sole">
 <collision>
      <geometry>
        <box size="0.08 0.08 0.001"/>
      </geometry>
      <origin rpy="0 0.00 0.002" xyz="0.0 0.005 0"/>
    </collision>
    <inertial>
      <mass value="2e-06"/>
      <inertia ixx="1.1e-09" ixy="0" ixz="0" iyy="1.1e-09" iyz="0" izz="1.1e-09"/>
    </inertial>
  </link>-->
  <link name="L_HIP_Y_LINK">
    <inertial>
      <origin rpy="0 0 0" xyz="-0.01667657 2e-08 0.04993135"/>
      <mass value="1.1356"/>
      <inertia ixx="0.00151524" ixy="-2.8e-07" ixz="-0.00048566" iyy="0.00231285" iyz="-0" izz="0.00149651"/>
    </inertial>
    <visual>
      <origin rpy="0 0 0" xyz="0 0 0"/>
      <geometry>
        <mesh filename="./meshes/HIP_Y.dae"/>
      </geometry>
    </visual>
    <collision>
      <origin rpy="0 0 0" xyz="0 0 0"/>
      <geometry>
        <mesh filename="./meshes/HIP_Y.dae"/>
      </geometry>
    </collision>
  </link>
  <link name="L_HIP_R_LINK">
    <inertial>
      <origin rpy="0 0 0" xyz="-0.00431692 0.00595121 -0.00052352"/>
      <mass value="0.58494148"/>
      <inertia ixx="0.00046475" ixy="-1.508e-05" ixz="-6.5e-07" iyy="0.00029804" iyz="2.39e-06" izz="0.00061763"/>
    </inertial>
    <visual>
      <origin rpy="0 0 0" xyz="0 0 0"/>
      <geometry>
        <mesh filename="./meshes/CHEST_P.dae"/>
      </geometry>
    </visual>
    <collision>
      <origin rpy="0 0 0" xyz="0 0 0"/>
      <geometry>
        <mesh filename="./meshes/CHEST_P.dae"/>
      </geometry>
    </collision>
  </link>
  <link name="L_HIP_P_LINK">
    <inertial>
      <origin rpy="0 0 0" xyz="0.00400906 -0.00541624 -0.18827632"/>
      <mass value="2.06366"/>
      <inertia ixx="0.03174381" ixy="9.784e-05" ixz="0.00063909" iyy="0.03068623" iyz="-0.00254187" izz="0.00291548"/>
    </inertial>
    <visual>
      <origin rpy="0 0 0" xyz="0 0 0"/>
      <geometry>
        <mesh filename="./meshes/L_HIP_P.dae"/>
      </geometry>
    </visual>
    <collision>
      <origin rpy="0 0 0" xyz="0 0 0"/>
      <geometry>
        <mesh filename="./meshes/L_HIP_P.dae"/>
      </geometry>
    </collision>
  </link>
  <link name="L_KNEE_P_LINK">
    <inertial>
      <origin rpy="0 0 0" xyz="-0.01122115 -0.00133701 -0.15252868"/>
      <mass value="2.08123"/>
      <inertia ixx="0.01900442" ixy="-4.75e-06" ixz="-0.0014589" iyy="0.01944097" iyz="2.008e-05" izz="0.00189659"/>
    </inertial>
    <visual>
      <origin rpy="0 0 0" xyz="0 0 0"/>
      <geometry>
        <mesh filename="./meshes/L_KNEE_P.dae"/>
      </geometry>
    </visual>
    <collision>
      <origin rpy="0 0 0" xyz="0 0 0"/>
      <geometry>
        <mesh filename="./meshes/L_KNEE_P.dae"/>
      </geometry>
    </collision>
  </link>
  <link name="L_ANKLE_P_LINK">
    <inertial>
      <origin rpy="0 0 0" xyz="-0.00368911 -0.00015844 0.00129883"/>
      <mass value="0.26784726"/>
      <inertia ixx="8.094e-05" ixy="-1.6e-07" ixz="-1.33e-06" iyy="0.00015522" iyz="-7e-08" izz="0.00017313"/>
    </inertial>
    <visual>
      <origin rpy="0 0 0" xyz="0 0 0"/>
      <geometry>
        <mesh filename="./meshes/L_ANKLE_P.dae"/>
      </geometry>
    </visual>
    <collision>
      <origin rpy="0 0 0" xyz="0 0 0"/>
      <geometry>
        <mesh filename="./meshes/L_ANKLE_P.dae"/>
      </geometry>
    </collision>
  </link>
  <link name="L_ANKLE_R_LINK">
    <inertial>
      <origin rpy="0 0 0" xyz="-0.00340792 0 -0.04591586"/>
      <mass value="0.72287828"/>
      <inertia ixx="0.00092215" ixy="-0" ixz="0.00011963" iyy="0.00102289" iyz="-0" izz="0.00089314"/>
    </inertial>
    <visual>
      <origin rpy="0 0 0" xyz="0 0 0"/>
      <geometry>
        <mesh filename="./meshes/L_ANKLE_R.dae"/>
      </geometry>
    </visual>
    <collision>
      <origin rpy="0 0 0" xyz="0 0 0"/>
      <geometry>
        <mesh filename="./meshes/L_ANKLE_R.dae"/>
      </geometry>
    </collision>
  </link>

  <link name="l_sole">
    <inertial>
      <origin rpy="0 0 0" xyz="0 0 0"/>
      <mass value="0.001"/>
      <inertia ixx="0.00001" ixy="0" ixz="0" iyy="0.00001" iyz="0" izz="0.00001"/>
    </inertial>

   <visual>
      <geometry>
        <box size="0.18 0.1 0.007"/>
      </geometry>
      <origin rpy="0 0 0" xyz="0.0 0.010 0.0029"/>
    </visual>
   <collision>
      <geometry>
        <box size="0.18 0.1 0.007"/>
      </geometry>
      <origin rpy="0 0 0" xyz="0.0 0.010 0.0029"/>
    </collision>
    <!--inertial>
      <mass value="1.0"/>
      <mu value="0.5"/>
      <inertia ixx="1.1e-09" ixy="0" ixz="0" iyy="1.1e-09" iyz="0" izz="1.1e-09"/>
    </inertial>
-->

  </link>
<!--
  <link name="l_sole">
   <collision>
      <geometry>
        <box size="0.14 0.078 0.007"/>
      </geometry>
      <origin rpy="0 0.00 0.002" xyz="0.0 0.005 0"/>
    </collision>
    <inertial>
      <mass value="2e-06"/>
      <inertia ixx="1.1e-09" ixy="0" ixz="0" iyy="1.1e-09" iyz="0" izz="1.1e-09"/>
    </inertial>
  </link>-->
  <link name="CHEST_P_LINK">
    <inertial>
      <origin rpy="0 0 0" xyz="-0.00442006 0.00280574 0.03664874"/>
      <mass value="1.24072"/>
      <inertia ixx="0.00250228" ixy="-1.572e-05" ixz="-1.986e-05" iyy="0.00266086" iyz="0.00013179" izz="0.0015461"/>
    </inertial>
    <visual>
      <origin rpy="0 0 0" xyz="0 0 0"/>
      <geometry>
        <mesh filename="./meshes/CHEST_P.dae"/>
      </geometry>
    </visual>
    <visual>
      <origin rpy="0 0 0" xyz="0 0 0"/>
      <geometry>
        <mesh filename="./meshes/CHEST_R.dae"/>
      </geometry>
    </visual>
    <collision>
      <origin rpy="0 0 0" xyz="0 0 0"/>
      <geometry>
        <mesh filename="./meshes/CHEST_P.dae"/>
      </geometry>
    </collision>
    <collision>
      <origin rpy="0 0 0" xyz="0 0 0"/>
      <geometry>
        <mesh filename="./meshes/CHEST_P.dae"/>
      </geometry>
    </collision>
  </link>
  <link name="torso">
    <inertial>
      <origin rpy="0 0 0" xyz="-0.02868847 -0.00245957 0.20400698"/>
      <mass value="6.67348"/>
      <inertia ixx="0.06656275" ixy="-9.681e-05" ixz="0.00599103" iyy="0.05508979" iyz="-0.00017557" izz="0.04262738"/>
    </inertial>
    <visual>
      <origin rpy="0 0 0" xyz="0 0 0"/>
      <geometry>
        <mesh filename="./meshes/CHEST_Y.dae"/>
      </geometry>
    </visual>
    <collision>
      <origin rpy="0 0 0" xyz="0 0 0"/>
      <geometry>
        <mesh filename="./meshes/CHEST_Y.dae"/>
      </geometry>
    </collision>
  </link>
  <link name="NECK_Y_LINK">
    <inertial>
      <origin rpy="0 0 0" xyz="-0.01142441 0.00157484 -0.02134892"/>
      <mass value="0.41214752"/>
      <inertia ixx="0.00061014" ixy="4.35e-06" ixz="7.329e-05" iyy="0.00068918" iyz="-1.384e-05" izz="0.00040587"/>
    </inertial>
    <visual>
      <origin rpy="0 0 0" xyz="0 0 0"/>
      <geometry>
        <mesh filename="./meshes/NECK_Y.dae"/>
      </geometry>
    </visual>
    <collision>
      <origin rpy="0 0 0" xyz="0 0 0"/>
      <geometry>
        <mesh filename="./meshes/NECK_Y.dae"/>
      </geometry>
    </collision>
  </link>
  <link name="NECK_P_LINK">
    <inertial>
      <origin rpy="0 0 0" xyz="0.00532833 -0.00053047 0.0176936"/>
      <mass value="0.22297511"/>
      <inertia ixx="0.00069884" ixy="-7e-07" ixz="3.33e-05" iyy="0.00093286" iyz="-1.51e-06" izz="0.00100342"/>
    </inertial>
    <visual>
      <origin rpy="0 0 0" xyz="0 0 0"/>
      <geometry>
        <mesh filename="./meshes/NECK_P.dae"/>
      </geometry>
    </visual>
    <collision>
      <origin rpy="0 0 0" xyz="0 0 0"/>
      <geometry>
        <mesh filename="./meshes/NECK_P.dae"/>
      </geometry>
    </collision>
  </link>
  <link name="R_SHOULDER_P_LINK">
    <inertial>
      <origin rpy="0 0 0" xyz="0.00141599 0.04257567 0.00031503"/>
      <mass value="0.42049079"/>
      <inertia ixx="0.00044203" ixy="-4.93e-06" ixz="-6.1e-07" iyy="0.00014181" iyz="-3.34e-06" izz="0.00044502"/>
    </inertial>
    <visual>
      <origin rpy="0 0 0" xyz="0 0 0"/>
      <geometry>
        <mesh filename="./meshes/R_SHOULDER_P.dae"/>
      </geometry>
    </visual>
    <collision>
      <origin rpy="0 0 0" xyz="0 0 0"/>
      <geometry>
        <mesh filename="./meshes/R_SHOULDER_P.dae"/>
      </geometry>
    </collision>
  </link>
  <link name="R_SHOULDER_R_LINK">
    <inertial>
      <origin rpy="0 0 0" xyz="0.00019752 -0.00272557 -0.04191141"/>
      <mass value="0.52070922"/>
      <inertia ixx="0.00062647" ixy="-7.3e-06" ixz="-6.476e-05" iyy="0.00071812" iyz="1.818e-05" izz="0.00029856"/>
    </inertial>
    <visual>
      <origin rpy="0 0 0" xyz="0 0 0"/>
      <geometry>
        <mesh filename="./meshes/R_SHOULDER_R.dae"/>
      </geometry>
    </visual>
    <collision>
      <origin rpy="0 0 0" xyz="0 0 0"/>
      <geometry>
        <mesh filename="./meshes/R_SHOULDER_R.dae"/>
      </geometry>
    </collision>
  </link>
  <link name="R_SHOULDER_Y_LINK">
    <inertial>
      <origin rpy="0 0 0" xyz="-0.00273859 -0.00036268 -0.17426645"/>
      <mass value="1.0874"/>
      <inertia ixx="0.00553694" ixy="1.18e-05" ixz="-4.295e-05" iyy="0.00556222" iyz="-9.379e-05" izz="0.00071841"/>
    </inertial>
    <visual>
      <origin rpy="0 0 0" xyz="0 0 0"/>
      <geometry>
        <mesh filename="./meshes/SHOULDER_Y.dae"/>
      </geometry>
    </visual>
    <collision>
      <origin rpy="0 0 0" xyz="0 0 0"/>
      <geometry>
        <mesh filename="./meshes/SHOULDER_Y.dae"/>
      </geometry>
    </collision>
  </link>
  <link name="R_ELBOW_P_LINK">
    <inertial>
      <origin rpy="0 0 0" xyz="-0.01222096 0.00049299 -0.07271909"/>
      <mass value="0.6594031"/>
      <inertia ixx="0.00121955" ixy="3.9e-06" ixz="4.22e-05" iyy="0.00135563" iyz="-1.497e-05" izz="0.00047041"/>
    </inertial>
    <visual>
      <origin rpy="0 0 0" xyz="0 0 0"/>
      <geometry>
        <mesh filename="./meshes/ELBOW_P.dae"/>
      </geometry>
    </visual>
    <collision>
      <origin rpy="0 0 0" xyz="0 0 0"/>
      <geometry>
        <mesh filename="./meshes/ELBOW_P.dae"/>
      </geometry>
    </collision>
  </link>
  <link name="R_WRIST_Y_LINK">
    <inertial>
      <origin rpy="0 0 0" xyz="-0.00749481 9.419e-05 -0.17044123"/>
      <mass value="0.38384092"/>
      <inertia ixx="0.00027044" ixy="-9.74e-06" ixz="1.069e-05" iyy="0.00027334" iyz="1.745e-05" izz="0.00022347"/>
    </inertial>
    <visual>
      <origin rpy="0 0 0" xyz="0 0 0"/>
      <geometry>
        <mesh filename="./meshes/R_WRIST_Y.dae"/>
      </geometry>
    </visual>
    <collision>
      <origin rpy="0 0 0" xyz="0 0 0"/>
      <geometry>
        <mesh filename="./meshes/R_WRIST_Y.dae"/>
      </geometry>
    </collision>
  </link>
  <link name="R_WRIST_P_LINK">
    <inertial>
      <origin rpy="0 0 0" xyz="0.00255098 0.00162183 0.01074678"/>
      <mass value="0.25425855"/>
      <inertia ixx="8.763e-05" ixy="1.53e-06" ixz="-3.48e-06" iyy="9.159e-05" iyz="4.48e-06" izz="5.571e-05"/>
    </inertial>
    <visual>
      <origin rpy="0 0 0" xyz="0 0 0"/>
      <geometry>
        <mesh filename="./meshes/WRIST_P.dae"/>
      </geometry>
    </visual>
    <collision>
      <origin rpy="0 0 0" xyz="0 0 0"/>
      <geometry>
        <mesh filename="./meshes/WRIST_P.dae"/>
      </geometry>
    </collision>
  </link>
  <link name="r_wrist">
    <inertial>
      <origin rpy="0 0 0" xyz="-0.00357307 -0.00756083 -0.07562434"/>
      <mass value="0.38811052"/>
      <inertia ixx="0.00041744" ixy="-2.58e-06" ixz="-3.079e-05" iyy="0.00053272" iyz="-4.178e-05" izz="0.00022506"/>
    </inertial>
    <visual>
      <origin rpy="0 0 0" xyz="0 0 0"/>
      <geometry>
        <mesh filename="./meshes/R_WRIST_R.dae"/>
      </geometry>
    </visual>
    <collision>
      <origin rpy="0 0 0" xyz="0 0 0"/>
      <geometry>
        <mesh filename="./meshes/R_WRIST_R.dae"/>
      </geometry>
    </collision>
  </link>
  <link name="R_HAND_J0_LINK">
    <inertial>
      <origin rpy="0 0 0" xyz="0.03905018 0.0103447 -0.02583122"/>
      <mass value="0.02982352"/>
      <inertia ixx="1.307e-05" ixy="-6.2e-06" ixz="1.249e-05" iyy="2.885e-05" iyz="4.36e-06" izz="2.119e-05"/>
    </inertial>
    <visual>
      <origin rpy="0 0 0" xyz="0 0 0"/>
      <geometry>
        <mesh filename="./meshes/R_THUMB.dae"/>
      </geometry>
    </visual>
    <collision>
      <origin rpy="0 0 0" xyz="0 0 0"/>
      <geometry>
        <mesh filename="./meshes/R_THUMB.dae"/>
      </geometry>
    </collision>
  </link>
  <link name="R_HAND_J1_LINK">
    <inertial>
      <origin rpy="0 0 0" xyz="-0.00520681 -8.854e-05 -0.01902284"/>
      <mass value="0.07696483"/>
      <inertia ixx="2.17e-05" ixy="-3e-08" ixz="-2.2e-07" iyy="5.741e-05" iyz="1e-07" izz="3.728e-05"/>
    </inertial>
    <visual>
      <origin rpy="0 0 0" xyz="0 0 0"/>
      <geometry>
        <mesh filename="./meshes/R_F1.dae"/>
      </geometry>
    </visual>
    <collision>
      <origin rpy="0 0 0" xyz="0 0 0"/>
      <geometry>
        <mesh filename="./meshes/R_F1.dae"/>
      </geometry>
    </collision>
  </link>
  <link name="R_F22_LINK">
    <inertial>
      <origin rpy="0 0 0" xyz="-0.00031853 0.00034526 -0.01168186"/>
      <mass value="0.00446884"/>
      <inertia ixx="3.2e-07" ixy="-0" ixz="-0" iyy="3.4e-07" iyz="-0" izz="9e-08"/>
    </inertial>
    <visual>
      <origin rpy="0 0 0" xyz="0 0 0"/>
      <geometry>
        <mesh filename="./meshes/F2.dae"/>
      </geometry>
    </visual>
    <collision>
      <origin rpy="0 0 0" xyz="0 0 0"/>
      <geometry>
        <mesh filename="./meshes/F2.dae"/>
      </geometry>
    </collision>
  </link>
  <link name="R_F23_LINK">
    <inertial>
      <origin rpy="0 0 0" xyz="-0.00035576 -0.00103228 -0.00714888"/>
      <mass value="0.0028745"/>
      <inertia ixx="1.6e-07" ixy="0" ixz="1e-08" iyy="2.1e-07" iyz="-2e-08" izz="7e-08"/>
    </inertial>
    <visual>
      <origin rpy="0 0 0" xyz="0 0 0"/>
      <geometry>
        <mesh filename="./meshes/F3.dae"/>
      </geometry>
    </visual>
    <collision>
      <origin rpy="0 0 0" xyz="0 0 0"/>
      <geometry>
        <mesh filename="./meshes/F3.dae"/>
      </geometry>
    </collision>
  </link>
  <link name="R_F32_LINK">
    <inertial>
      <origin rpy="0 0 0" xyz="-0.00031853 0.00034526 -0.01168186"/>
      <mass value="0.00446884"/>
      <inertia ixx="3.2e-07" ixy="-0" ixz="-0" iyy="3.4e-07" iyz="-0" izz="9e-08"/>
    </inertial>
    <visual>
      <origin rpy="0 0 0" xyz="0 0 0"/>
      <geometry>
        <mesh filename="./meshes/F2.dae"/>
      </geometry>
    </visual>
    <collision>
      <origin rpy="0 0 0" xyz="0 0 0"/>
      <geometry>
        <mesh filename="./meshes/F2.dae"/>
      </geometry>
    </collision>
  </link>
  <link name="R_F33_LINK">
    <inertial>
      <origin rpy="0 0 0" xyz="-0.00035576 -0.00103228 -0.00714888"/>
      <mass value="0.0028745"/>
      <inertia ixx="1.6e-07" ixy="0" ixz="1e-08" iyy="2.1e-07" iyz="-2e-08" izz="7e-08"/>
    </inertial>
    <visual>
      <origin rpy="0 0 0" xyz="0 0 0"/>
      <geometry>
        <mesh filename="./meshes/F3.dae"/>
      </geometry>
    </visual>
    <collision>
      <origin rpy="0 0 0" xyz="0 0 0"/>
      <geometry>
        <mesh filename="./meshes/F3.dae"/>
      </geometry>
    </collision>
  </link>
  <link name="R_F42_LINK">
    <inertial>
      <origin rpy="0 0 0" xyz="-0.00031853 0.00034526 -0.01168186"/>
      <mass value="0.00446884"/>
      <inertia ixx="3.2e-07" ixy="-0" ixz="-0" iyy="3.4e-07" iyz="-0" izz="9e-08"/>
    </inertial>
    <visual>
      <origin rpy="0 0 0" xyz="0 0 0"/>
      <geometry>
        <mesh filename="./meshes/F2.dae"/>
      </geometry>
    </visual>
    <collision>
      <origin rpy="0 0 0" xyz="0 0 0"/>
      <geometry>
        <mesh filename="./meshes/F2.dae"/>
      </geometry>
    </collision>
  </link>
  <link name="R_F43_LINK">
    <inertial>
      <origin rpy="0 0 0" xyz="-0.00035576 -0.00103228 -0.00714888"/>
      <mass value="0.0028745"/>
      <inertia ixx="1.6e-07" ixy="0" ixz="1e-08" iyy="2.1e-07" iyz="-2e-08" izz="7e-08"/>
    </inertial>
    <visual>
      <origin rpy="0 0 0" xyz="0 0 0"/>
      <geometry>
        <mesh filename="./meshes/F3.dae"/>
      </geometry>
    </visual>
    <collision>
      <origin rpy="0 0 0" xyz="0 0 0"/>
      <geometry>
        <mesh filename="./meshes/F3.dae"/>
      </geometry>
    </collision>
  </link>
  <link name="R_F52_LINK">
    <inertial>
      <origin rpy="0 0 0" xyz="-0.00031853 0.00034526 -0.01168186"/>
      <mass value="0.00446884"/>
      <inertia ixx="3.2e-07" ixy="-0" ixz="-0" iyy="3.4e-07" iyz="-0" izz="9e-08"/>
    </inertial>
    <visual>
      <origin rpy="0 0 0" xyz="0 0 0"/>
      <geometry>
        <mesh filename="./meshes/F2.dae"/>
      </geometry>
    </visual>
    <collision>
      <origin rpy="0 0 0" xyz="0 0 0"/>
      <geometry>
        <mesh filename="./meshes/F2.dae"/>
      </geometry>
    </collision>
  </link>
  <link name="R_F53_LINK">
    <inertial>
      <origin rpy="0 0 0" xyz="-0.00035576 -0.00103228 -0.00714888"/>
      <mass value="0.0028745"/>
      <inertia ixx="1.6e-07" ixy="0" ixz="1e-08" iyy="2.1e-07" iyz="-2e-08" izz="7e-08"/>
    </inertial>
    <visual>
      <origin rpy="0 0 0" xyz="0 0 0"/>
      <geometry>
        <mesh filename="./meshes/F3.dae"/>
      </geometry>
    </visual>
    <collision>
      <origin rpy="0 0 0" xyz="0 0 0"/>
      <geometry>
        <mesh filename="./meshes/F3.dae"/>
      </geometry>
    </collision>
  </link>
  <link name="L_SHOULDER_P_LINK">
    <inertial>
      <origin rpy="0 0 0" xyz="0.00141599 -0.04257567 -0.00031503"/>
      <mass value="0.42049079"/>
      <inertia ixx="0.00044203" ixy="4.93e-06" ixz="6.1e-07" iyy="0.00014181" iyz="-3.34e-06" izz="0.00044502"/>
    </inertial>
    <visual>
      <origin rpy="0 0 0" xyz="0 0 0"/>
      <geometry>
        <mesh filename="./meshes/L_SHOULDER_P.dae"/>
      </geometry>
    </visual>
    <collision>
      <origin rpy="0 0 0" xyz="0 0 0"/>
      <geometry>
        <mesh filename="./meshes/L_SHOULDER_P.dae"/>
      </geometry>
    </collision>
  </link>
  <link name="L_SHOULDER_R_LINK">
    <inertial>
      <origin rpy="0 0 0" xyz="0.00019752 -8.916e-05 -0.04191141"/>
      <mass value="0.52070922"/>
      <inertia ixx="0.00063033" ixy="-6.01e-06" ixz="-6.476e-05" iyy="0.00071812" iyz="-2.895e-05" izz="0.00030242"/>
    </inertial>
    <visual>
      <origin rpy="0 0 0" xyz="0 0 0"/>
      <geometry>
        <mesh filename="./meshes/L_SHOULDER_R.dae"/>
      </geometry>
    </visual>
    <collision>
      <origin rpy="0 0 0" xyz="0 0 0"/>
      <geometry>
        <mesh filename="./meshes/L_SHOULDER_R.dae"/>
      </geometry>
    </collision>
  </link>
  <link name="L_SHOULDER_Y_LINK">
    <inertial>
      <origin rpy="0 0 0" xyz="-0.00273859 -0.00036268 -0.17426645"/>
      <mass value="1.0874"/>
      <inertia ixx="0.00553694" ixy="1.18e-05" ixz="-4.295e-05" iyy="0.00556222" iyz="-9.379e-05" izz="0.00071841"/>
    </inertial>
    <visual>
      <origin rpy="0 0 0" xyz="0 0 0"/>
      <geometry>
        <mesh filename="./meshes/SHOULDER_Y.dae"/>
      </geometry>
    </visual>
    <collision>
      <origin rpy="0 0 0" xyz="0 0 0"/>
      <geometry>
        <mesh filename="./meshes/SHOULDER_Y.dae"/>
      </geometry>
    </collision>
  </link>
  <link name="L_ELBOW_P_LINK">
    <inertial>
      <origin rpy="0 0 0" xyz="-0.01222096 0.00049299 -0.07271909"/>
      <mass value="0.6594031"/>
      <inertia ixx="0.00121955" ixy="3.9e-06" ixz="4.22e-05" iyy="0.00135563" iyz="-1.497e-05" izz="0.00047041"/>
    </inertial>
    <visual>
      <origin rpy="0 0 0" xyz="0 0 0"/>
      <geometry>
        <mesh filename="./meshes/ELBOW_P.dae"/>
      </geometry>
    </visual>
    <collision>
      <origin rpy="0 0 0" xyz="0 0 0"/>
      <geometry>
        <mesh filename="./meshes/ELBOW_P.dae"/>
      </geometry>
    </collision>
  </link>
  <link name="L_WRIST_Y_LINK">
    <inertial>
      <origin rpy="0 0 0" xyz="-0.00749574 -9.418e-05 -0.17044123"/>
      <mass value="0.38384092"/>
      <inertia ixx="0.00027044" ixy="9.76e-06" ixz="1.07e-05" iyy="0.00027334" iyz="-1.745e-05" izz="0.00022346"/>
    </inertial>
    <visual>
      <origin rpy="0 0 0" xyz="0 0 0"/>
      <geometry>
        <mesh filename="./meshes/L_WRIST_Y.dae"/>
      </geometry>
    </visual>
    <collision>
      <origin rpy="0 0 0" xyz="0 0 0"/>
      <geometry>
        <mesh filename="./meshes/L_WRIST_Y.dae"/>
      </geometry>
    </collision>
  </link>
  <link name="L_WRIST_P_LINK">
    <inertial>
      <origin rpy="0 0 0" xyz="-0.00255098 -0.00162183 0.01074678"/>
      <mass value="0.25425855"/>
      <inertia ixx="8.763e-05" ixy="1.53e-06" ixz="3.48e-06" iyy="9.159e-05" iyz="-4.48e-06" izz="5.571e-05"/>
    </inertial>
    <visual>
      <origin rpy="0 0 0" xyz="0 0 0"/>
      <geometry>
        <mesh filename="./meshes/WRIST_P.dae"/>
      </geometry>
    </visual>
    <collision>
      <origin rpy="0 0 0" xyz="0 0 0"/>
      <geometry>
        <mesh filename="./meshes/WRIST_P.dae"/>
      </geometry>
    </collision>
  </link>
  <link name="l_wrist">
    <inertial>
      <origin rpy="0 0 0" xyz="-0.00241915 0.00756006 -0.07562466"/>
      <mass value="0.38811052"/>
      <inertia ixx="0.00041745" ixy="4.71e-06" ixz="-6.41e-05" iyy="0.00053559" iyz="4.177e-05" izz="0.00022792"/>
    </inertial>
    <visual>
      <origin rpy="0 0 0" xyz="0 0 0"/>
      <geometry>
        <mesh filename="./meshes/L_WRIST_R.dae"/>
      </geometry>
    </visual>
    <collision>
      <origin rpy="0 0 0" xyz="0 0 0"/>
      <geometry>
        <mesh filename="./meshes/L_WRIST_R.dae"/>
      </geometry>
    </collision>
  </link>
  <link name="L_HAND_J0_LINK">
    <inertial>
      <origin rpy="0 0 0" xyz="0.03905018 -0.0103447 -0.02583122"/>
      <mass value="0.02982352"/>
      <inertia ixx="1.307e-05" ixy="6.2e-06" ixz="1.249e-05" iyy="2.885e-05" iyz="-4.36e-06" izz="2.119e-05"/>
    </inertial>
    <visual>
      <origin rpy="0 0 0" xyz="0 0 0"/>
      <geometry>
        <mesh filename="./meshes/L_THUMB.dae"/>
      </geometry>
    </visual>
    <collision>
      <origin rpy="0 0 0" xyz="0 0 0"/>
      <geometry>
        <mesh filename="./meshes/L_THUMB.dae"/>
      </geometry>
    </collision>
  </link>
  <link name="L_HAND_J1_LINK">
    <inertial>
      <origin rpy="0 0 0" xyz="-0.00479332 8.854e-05 -0.01902284"/>
      <mass value="0.07696483"/>
      <inertia ixx="2.17e-05" ixy="-3e-08" ixz="2.3e-07" iyy="5.741e-05" iyz="-1e-07" izz="3.728e-05"/>
    </inertial>
    <visual>
      <origin rpy="0 0 0" xyz="0 0 0"/>
      <geometry>
        <mesh filename="./meshes/L_F1.dae"/>
      </geometry>
    </visual>
    <collision>
      <origin rpy="0 0 0" xyz="0 0 0"/>
      <geometry>
        <mesh filename="./meshes/L_F1.dae"/>
      </geometry>
    </collision>
  </link>
  <link name="L_F22_LINK">
    <inertial>
      <origin rpy="0 0 0" xyz="0.00031853 -0.00034526 -0.01168186"/>
      <mass value="0.00446884"/>
      <inertia ixx="3.2e-07" ixy="-0" ixz="0" iyy="3.4e-07" iyz="0" izz="9e-08"/>
    </inertial>
    <visual>
      <origin rpy="0 0 0" xyz="0 0 0"/>
      <geometry>
        <mesh filename="./meshes/F2.dae"/>
      </geometry>
    </visual>
    <collision>
      <origin rpy="0 0 0" xyz="0 0 0"/>
      <geometry>
        <mesh filename="./meshes/F2.dae"/>
      </geometry>
    </collision>
  </link>
  <link name="L_F23_LINK">
    <inertial>
      <origin rpy="0 0 0" xyz="0.00035576 0.00103228 -0.00714888"/>
      <mass value="0.0028745"/>
      <inertia ixx="1.6e-07" ixy="0" ixz="-1e-08" iyy="2.1e-07" iyz="2e-08" izz="7e-08"/>
    </inertial>
    <visual>
      <origin rpy="0 0 0" xyz="0 0 0"/>
      <geometry>
        <mesh filename="./meshes/F3.dae"/>
      </geometry>
    </visual>
    <collision>
      <origin rpy="0 0 0" xyz="0 0 0"/>
      <geometry>
        <mesh filename="./meshes/F3.dae"/>
      </geometry>
    </collision>
  </link>
  <link name="L_F32_LINK">
    <inertial>
      <origin rpy="0 0 0" xyz="0.00031853 -0.00034526 -0.01168186"/>
      <mass value="0.00446884"/>
      <inertia ixx="3.2e-07" ixy="-0" ixz="0" iyy="3.4e-07" iyz="0" izz="9e-08"/>
    </inertial>
    <visual>
      <origin rpy="0 0 0" xyz="0 0 0"/>
      <geometry>
        <mesh filename="./meshes/F2.dae"/>
      </geometry>
    </visual>
    <collision>
      <origin rpy="0 0 0" xyz="0 0 0"/>
      <geometry>
        <mesh filename="./meshes/F2.dae"/>
      </geometry>
    </collision>
  </link>
  <link name="L_F33_LINK">
    <inertial>
      <origin rpy="0 0 0" xyz="0.00035576 0.00103228 -0.00714888"/>
      <mass value="0.0028745"/>
      <inertia ixx="1.6e-07" ixy="0" ixz="-1e-08" iyy="2.1e-07" iyz="2e-08" izz="7e-08"/>
    </inertial>
    <visual>
      <origin rpy="0 0 0" xyz="0 0 0"/>
      <geometry>
        <mesh filename="./meshes/F3.dae"/>
      </geometry>
    </visual>
    <collision>
      <origin rpy="0 0 0" xyz="0 0 0"/>
      <geometry>
        <mesh filename="./meshes/F3.dae"/>
      </geometry>
    </collision>
  </link>
  <link name="L_F42_LINK">
    <inertial>
      <origin rpy="0 0 0" xyz="0.00031853 -0.00034526 -0.01168186"/>
      <mass value="0.00446884"/>
      <inertia ixx="3.2e-07" ixy="-0" ixz="0" iyy="3.4e-07" iyz="0" izz="9e-08"/>
    </inertial>
    <visual>
      <origin rpy="0 0 0" xyz="0 0 0"/>
      <geometry>
        <mesh filename="./meshes/F2.dae"/>
      </geometry>
    </visual>
    <collision>
      <origin rpy="0 0 0" xyz="0 0 0"/>
      <geometry>
        <mesh filename="./meshes/F2.dae"/>
      </geometry>
    </collision>
  </link>
  <link name="L_F43_LINK">
    <inertial>
      <origin rpy="0 0 0" xyz="0.00035576 0.00103228 -0.00714888"/>
      <mass value="0.0028745"/>
      <inertia ixx="1.6e-07" ixy="0" ixz="-1e-08" iyy="2.1e-07" iyz="2e-08" izz="7e-08"/>
    </inertial>
    <visual>
      <origin rpy="0 0 0" xyz="0 0 0"/>
      <geometry>
        <mesh filename="./meshes/F3.dae"/>
      </geometry>
    </visual>
    <collision>
      <origin rpy="0 0 0" xyz="0 0 0"/>
      <geometry>
        <mesh filename="./meshes/F3.dae"/>
      </geometry>
    </collision>
  </link>
  <link name="L_F52_LINK">
    <inertial>
      <origin rpy="0 0 0" xyz="0.00031853 -0.00034526 -0.01168186"/>
      <mass value="0.00446884"/>
      <inertia ixx="3.2e-07" ixy="-0" ixz="0" iyy="3.4e-07" iyz="0" izz="9e-08"/>
    </inertial>
    <visual>
      <origin rpy="0 0 0" xyz="0 0 0"/>
      <geometry>
        <mesh filename="./meshes/F2.dae"/>
      </geometry>
    </visual>
    <collision>
      <origin rpy="0 0 0" xyz="0 0 0"/>
      <geometry>
        <mesh filename="./meshes/F2.dae"/>
      </geometry>
    </collision>
  </link>
  <link name="L_F53_LINK">
    <inertial>
      <origin rpy="0 0 0" xyz="0.00035576 0.00103228 -0.00714888"/>
      <mass value="0.0028745"/>
      <inertia ixx="1.6e-07" ixy="0" ixz="-1e-08" iyy="2.1e-07" iyz="2e-08" izz="7e-08"/>
    </inertial>
    <visual>
      <origin rpy="0 0 0" xyz="0 0 0"/>
      <geometry>
        <mesh filename="./meshes/F3.dae"/>
      </geometry>
    </visual>
    <collision>
      <origin rpy="0 0 0" xyz="0 0 0"/>
      <geometry>
        <mesh filename="./meshes/F3.dae"/>
      </geometry>
    </collision>
  </link>
  <!--   Joints following below -->
  <joint name="R_HIP_Y" type="revolute">
    <origin rpy="0 0 0" xyz="0 -0.0875 0"/>
    <axis xyz="0 0 1"/>
    <parent link="body"/>
    <child link="R_HIP_Y_LINK"/>
    <limit effort="41.65" lower="-0.78539815" upper="0.78539815" velocity="5.0789081233"/>
  </joint>
  <joint name="R_HIP_R" type="revolute">
    <origin rpy="0 0 0" xyz="0 0 0"/>
    <axis xyz="1 0 0"/>
    <parent link="R_HIP_Y_LINK"/>
    <child link="R_HIP_R_LINK"/>
    <limit effort="224.91" lower="-0.436332305555556" upper="0.436332305555556" velocity="2.82743338823"/>
  </joint>
  <joint name="R_HIP_P" type="revolute">
    <origin rpy="0 0 0" xyz="0 0 0"/>
    <axis xyz="0 1 0"/>
    <parent link="R_HIP_R_LINK"/>
    <child link="R_HIP_P_LINK"/>
    <limit effort="114.95" lower="-1.34390350111111" upper="0.418879013333333" velocity="5.51873109481"/>
  </joint>
  <joint name="R_KNEE_P" type="revolute">
    <origin rpy="0 0 0" xyz="0 0.01905 -0.358"/>
    <axis xyz="0 1 0"/>
    <parent link="R_HIP_P_LINK"/>
    <child link="R_KNEE_P_LINK"/>
    <limit effort="242.76" lower="0.0122173045555556" upper="2.17642554011111" velocity="2.61799387799"/>
  </joint>
  <joint name="R_ANKLE_P" type="revolute">
    <origin rpy="0 0 0" xyz="0 0 -0.341150992963526"/>
    <axis xyz="0 1 0"/>
    <parent link="R_KNEE_P_LINK"/>
    <child link="R_ANKLE_P_LINK"/>
    <limit effort="163.41" lower="-0.989601669" upper="0.267035371" velocity="4.71238898038"/>
  </joint>
  <joint name="R_ANKLE_R" type="revolute">
    <origin rpy="0 0 0" xyz="0 0 0"/>
    <axis xyz="1 0 0"/>
    <parent link="R_ANKLE_P_LINK"/>
    <child link="R_ANKLE_R_LINK"/>
    <limit effort="42.07" lower="-0.593411935555556" upper="0.593411935555556" velocity="5.02654824574"/>
  </joint>
  <joint name="L_HIP_Y" type="revolute">
    <origin rpy="0 0 0" xyz="0 0.0875 0"/>
    <axis xyz="0 0 1"/>
    <parent link="body"/>
    <child link="L_HIP_Y_LINK"/>
    <limit effort="41.65" lower="-0.78539815" upper="0.78539815" velocity="5.0789081233"/>
  </joint>
  <joint name="L_HIP_R" type="revolute">
    <origin rpy="0 0 0" xyz="0 0 0"/>
    <axis xyz="1 0 0"/>
    <parent link="L_HIP_Y_LINK"/>
    <child link="L_HIP_R_LINK"/>
    <limit effort="224.91" lower="-0.436332305555556" upper="0.436332305555556" velocity="2.82743338823"/>
  </joint>
  <joint name="L_HIP_P" type="revolute">
    <origin rpy="0 0 0" xyz="0 0 0"/>
    <axis xyz="0 1 0"/>
    <parent link="L_HIP_R_LINK"/>
    <child link="L_HIP_P_LINK"/>
    <limit effort="114.95" lower="-1.34390350111111" upper="0.418879013333333" velocity="5.51873109481"/>
  </joint>
  <joint name="L_KNEE_P" type="revolute">
    <origin rpy="0 0 0" xyz="0 -0.01905 -0.358"/>
    <axis xyz="0 1 0"/>
    <parent link="L_HIP_P_LINK"/>
    <child link="L_KNEE_P_LINK"/>
    <limit effort="242.76" lower="0.0122173045555556" upper="2.17642554011111" velocity="2.61799387799"/>
  </joint>
  <joint name="L_ANKLE_P" type="revolute">
    <origin rpy="0 0 0" xyz="0 0 -0.341150992963526"/>
    <axis xyz="0 1 0"/>
    <parent link="L_KNEE_P_LINK"/>
    <child link="L_ANKLE_P_LINK"/>
    <limit effort="163.41" lower="-0.989601669" upper="0.267035371" velocity="4.71238898038"/>
  </joint>
  <joint name="L_ANKLE_R" type="revolute">
    <origin rpy="0 0 0" xyz="0 0 0"/>
    <axis xyz="1 0 0"/>
    <parent link="L_ANKLE_P_LINK"/>
    <child link="L_ANKLE_R_LINK"/>
    <limit effort="42.07" lower="-0.593411935555556" upper="0.593411935555556" velocity="5.02654824574"/>
  </joint>
  <joint name="CHEST_P" type="revolute">
    <origin rpy="0 0 0" xyz="0.01 0 0.197"/>
    <axis xyz="0 1 0"/>
    <parent link="body"/>
    <child link="CHEST_P_LINK"/>
    <limit effort="114.95" lower="-0.209439506666667" upper="0.523598766666667" velocity="5.51873109481"/>
  </joint>
  <joint name="CHEST_Y" type="revolute">
    <origin rpy="0 0 0" xyz="0 0 0"/>
    <axis xyz="0 0 1"/>
    <parent link="CHEST_P_LINK"/>
    <child link="torso"/>
    <limit effort="107.1" lower="-0.610865227777778" upper="0.610865227777778" velocity="5.92713813977"/>
  </joint>
  <joint name="NECK_Y" type="revolute">
    <origin rpy="0 0 0" xyz="-0.04 0 0.434"/>
    <axis xyz="0 0 1"/>
    <parent link="torso"/>
    <child link="NECK_Y_LINK"/>
    <limit effort="12.4" lower="-1.22173045555556" upper="1.22173045555556" velocity="4.1154863762"/>
  </joint>
  <joint name="NECK_P" type="revolute">
    <origin rpy="0 0 0" xyz="0 0 0"/>
    <axis xyz="0 1 0"/>
    <parent link="NECK_Y_LINK"/>
    <child link="NECK_P_LINK"/>
    <limit effort="12.4" lower="-0.523598766666667" upper="0.436332305555556" velocity="4.1154863762"/>
  </joint>
  <joint name="R_SHOULDER_P" type="revolute">
    <origin rpy="0 0 0" xyz="-0.04 -0.17 0.285"/>
    <axis xyz="0 1 0"/>
    <parent link="torso"/>
    <child link="R_SHOULDER_P_LINK"/>
    <limit effort="214.2" lower="-2.56563395666667" upper="1.04719753333333" velocity="2.96356906989"/>
  </joint>
  <joint name="R_SHOULDER_R" type="revolute">
    <origin rpy="0 0 0" xyz="0 0 0"/>
    <axis xyz="1 0 0"/>
    <parent link="R_SHOULDER_P_LINK"/>
    <child link="R_SHOULDER_R_LINK"/>
    <limit effort="60.6" lower="-1.55334300777778" upper="0.174532922222222" velocity="2.05250720035"/>
  </joint>
  <joint name="R_SHOULDER_Y" type="revolute">
    <origin rpy="0 0 0" xyz="0 0 0"/>
    <axis xyz="0 0 1"/>
    <parent link="R_SHOULDER_R_LINK"/>
    <child link="R_SHOULDER_Y_LINK"/>
    <limit effort="63.82" lower="-1.60570288444444" upper="1.60570288444444" velocity="2.94262511886"/>
  </joint>
  <joint name="R_ELBOW_P" type="revolute">
    <origin rpy="0 0 0" xyz="0 0 -0.283"/>
    <axis xyz="0 1 0"/>
    <parent link="R_SHOULDER_Y_LINK"/>
    <child link="R_ELBOW_P_LINK"/>
    <limit effort="46.99" lower="-2.14675494333333" upper="0.0349065844444444" velocity="2.64940980453"/>
  </joint>
  <joint name="R_WRIST_Y" type="fixed">
    <origin rpy="0 0 0" xyz="0 0 0"/>
    <axis xyz="0 0 1"/>
    <parent link="R_ELBOW_P_LINK"/>
    <child link="R_WRIST_Y_LINK"/>
    <limit effort="12.4" lower="-1.60570288444444" upper="1.60570288444444" velocity="4.1154863762"/>
  </joint>
  <joint name="R_WRIST_P" type="fixed">
    <origin rpy="0 0 0" xyz="0 0 -0.234"/>
    <axis xyz="0 1 0"/>
    <parent link="R_WRIST_Y_LINK"/>
    <child link="R_WRIST_P_LINK"/>
    <limit effort="12.4" lower="-0.715584981111111" upper="0.715584981111111" velocity="4.1154863762"/>
  </joint>
  <joint name="R_WRIST_R" type="fixed">
    <origin rpy="0 0 0" xyz="0 0 0"/>
    <axis xyz="1 0 0"/>
    <parent link="R_WRIST_P_LINK"/>
    <child link="r_wrist"/>
    <limit effort="12.4" lower="-1.60570288444444" upper="1.60570288444444" velocity="4.1154863762"/>
  </joint>
  <joint name="R_HAND_J0" type="fixed">
    <origin rpy="0 0.4118977034707 0" xyz="0.03419 0 -0.039"/>
    <axis xyz="0 0 1"/>
    <parent link="r_wrist"/>
    <child link="R_HAND_J0_LINK"/>
    <limit effort="1.06" lower="0" upper="1.5707963" velocity="16.9541283539"/>
  </joint>
  <joint name="R_HAND_J1" type="fixed">
    <origin rpy="0 0 0" xyz="0 0 -0.111"/>
    <axis xyz="1 0 0"/>
    <parent link="r_wrist"/>
    <child link="R_HAND_J1_LINK"/>
    <limit effort="1.59" lower="-0.174532922222222" upper="1.5707963" velocity="11.2992615774"/>
  </joint>
  <joint name="L_SHOULDER_P" type="revolute">
    <origin rpy="0 0 0" xyz="-0.04 0.17 0.285"/>
    <axis xyz="0 1 0"/>
    <parent link="torso"/>
    <child link="L_SHOULDER_P_LINK"/>
    <limit effort="214.2" lower="-2.56563395666667" upper="1.04719753333333" velocity="2.96356906989"/>
  </joint>
  <joint name="L_SHOULDER_R" type="revolute">
    <origin rpy="0 0 0" xyz="0 0 0"/>
    <axis xyz="1 0 0"/>
    <parent link="L_SHOULDER_P_LINK"/>
    <child link="L_SHOULDER_R_LINK"/>
    <limit effort="60.6" lower="-0.174532922222222" upper="1.55334300777778" velocity="2.05250720035"/>
  </joint>
  <joint name="L_SHOULDER_Y" type="revolute">
    <origin rpy="0 0 0" xyz="0 0 0"/>
    <axis xyz="0 0 1"/>
    <parent link="L_SHOULDER_R_LINK"/>
    <child link="L_SHOULDER_Y_LINK"/>
    <limit effort="63.82" lower="-1.60570288444444" upper="1.60570288444444" velocity="2.94262511886"/>
  </joint>
  <joint name="L_ELBOW_P" type="revolute">
    <origin rpy="0 0 0" xyz="0 0 -0.283"/>
    <axis xyz="0 1 0"/>
    <parent link="L_SHOULDER_Y_LINK"/>
    <child link="L_ELBOW_P_LINK"/>
    <limit effort="46.99" lower="-2.14675494333333" upper="0.0349065844444444" velocity="2.64940980453"/>
  </joint>
  <joint name="L_WRIST_Y" type="fixed">
    <origin rpy="0 0 0" xyz="0 0 0"/>
    <axis xyz="0 0 1"/>
    <parent link="L_ELBOW_P_LINK"/>
    <child link="L_WRIST_Y_LINK"/>
    <limit effort="12.4" lower="-1.60570288444444" upper="1.60570288444444" velocity="4.1154863762"/>
  </joint>
  <joint name="L_WRIST_P" type="fixed">
    <origin rpy="0 0 0" xyz="0 0 -0.234"/>
    <axis xyz="0 1 0"/>
    <parent link="L_WRIST_Y_LINK"/>
    <child link="L_WRIST_P_LINK"/>
    <limit effort="12.4" lower="-0.715584981111111" upper="0.715584981111111" velocity="4.1154863762"/>
  </joint>
  <joint name="L_WRIST_R" type="fixed">
    <origin rpy="0 0 0" xyz="0 0 0"/>
    <axis xyz="1 0 0"/>
    <parent link="L_WRIST_P_LINK"/>
    <child link="l_wrist"/>
    <limit effort="12.4" lower="-1.60570288444444" upper="1.60570288444444" velocity="4.1154863762"/>
  </joint>
  <joint name="L_HAND_J0" type="fixed">
    <origin rpy="0 0.4118977034707 0" xyz="0.03419 0 -0.039"/>
    <axis xyz="0 0 1"/>
    <parent link="l_wrist"/>
    <child link="L_HAND_J0_LINK"/>
    <limit effort="1.06" lower="-1.5707963" upper="0" velocity="16.9541283539"/>
  </joint>
  <joint name="L_HAND_J1" type="fixed">
    <origin rpy="0 0 0" xyz="0 0 -0.111"/>
    <axis xyz="1 0 0"/>
    <parent link="l_wrist"/>
    <child link="L_HAND_J1_LINK"/>
    <limit effort="1.59" lower="-1.5707963" upper="0.174532922222222" velocity="11.2992615774"/>
  </joint>
  <joint name="l_sole_joint" type="fixed">
    <parent link="l_ankle"/>
    <child link="l_sole"/>
    <origin rpy="0 0 0" xyz="0 0 -0.093"/>
  </joint>
  <joint name="r_sole_joint" type="fixed">
    <parent link="r_ankle"/>
    <child link="r_sole"/>
    <origin rpy="0 0 0" xyz="0 0 -0.093"/>
  </joint>

  <joint name="R_F22" type="fixed">
    <origin rpy="0 -0 3.1415926535" xyz="0.0253 0 -0.045"/>
    <axis xyz="1 0 0"/>
    <parent link="R_HAND_J1_LINK"/>
    <child link="R_F22_LINK"/>
    <limit effort="1" lower="-1.22173045555556" upper="0" velocity="1"/>
    <mimic joint="R_HAND_J1" multiplier="1" offset="0"/>
  </joint>
  <joint name="R_F23" type="fixed">
    <origin rpy="0 0 0" xyz="0 0 -0.024"/>
    <axis xyz="1 0 0"/>
    <parent link="R_F22_LINK"/>
    <child link="R_F23_LINK"/>
    <limit effort="1" lower="-1.22173045555556" upper="0" velocity="1"/>
    <mimic joint="R_HAND_J1" multiplier="1" offset="0"/>
  </joint>
  <joint name="R_F32" type="fixed">
    <origin rpy="0 -0 3.1415926535" xyz="0.0051 0 -0.045"/>
    <axis xyz="1 0 0"/>
    <parent link="R_HAND_J1_LINK"/>
    <child link="R_F32_LINK"/>
    <limit effort="1" lower="-1.22173045555556" upper="0" velocity="1"/>
    <mimic joint="R_HAND_J1" multiplier="1" offset="0"/>
  </joint>
  <joint name="R_F33" type="fixed">
    <origin rpy="0 0 0" xyz="0 0 -0.024"/>
    <axis xyz="1 0 0"/>
    <parent link="R_F32_LINK"/>
    <child link="R_F33_LINK"/>
    <limit effort="1" lower="-1.22173045555556" upper="0" velocity="1"/>
    <mimic joint="R_HAND_J1" multiplier="1" offset="0"/>
  </joint>
  <joint name="R_F42" type="fixed">
    <origin rpy="0 -0 3.1415926535" xyz="-0.0151 0 -0.045"/>
    <axis xyz="1 0 0"/>
    <parent link="R_HAND_J1_LINK"/>
    <child link="R_F42_LINK"/>
    <limit effort="1" lower="-1.22173045555556" upper="0" velocity="1"/>
    <mimic joint="R_HAND_J1" multiplier="1" offset="0"/>
  </joint>
  <joint name="R_F43" type="fixed">
    <origin rpy="0 0 0" xyz="0 0 -0.024"/>
    <axis xyz="1 0 0"/>
    <parent link="R_F42_LINK"/>
    <child link="R_F43_LINK"/>
    <limit effort="1" lower="-1.22173045555556" upper="0" velocity="1"/>
    <mimic joint="R_HAND_J1" multiplier="1" offset="0"/>
  </joint>
  <joint name="R_F52" type="fixed">
    <origin rpy="0 -0 3.1415926535" xyz="-0.0353 0 -0.045"/>
    <axis xyz="1 0 0"/>
    <parent link="R_HAND_J1_LINK"/>
    <child link="R_F52_LINK"/>
    <limit effort="1" lower="-1.22173045555556" upper="0" velocity="1"/>
    <mimic joint="R_HAND_J1" multiplier="1" offset="0"/>
  </joint>
  <joint name="R_F53" type="fixed">
    <origin rpy="0 0 0" xyz="0 0 -0.024"/>
    <axis xyz="1 0 0"/>
    <parent link="R_F52_LINK"/>
    <child link="R_F53_LINK"/>
    <limit effort="1" lower="-1.22173045555556" upper="0" velocity="1"/>
    <mimic joint="R_HAND_J1" multiplier="1" offset="0"/>
  </joint>
  <joint name="L_F22" type="fixed">
    <origin rpy="0 0 0" xyz="0.0253 0 -0.045"/>
    <axis xyz="1 0 0"/>
    <parent link="L_HAND_J1_LINK"/>
    <child link="L_F22_LINK"/>
    <limit effort="1" lower="-1.22173045555556" upper="0" velocity="1"/>
    <mimic joint="L_HAND_J1" multiplier="1" offset="0"/>
  </joint>
  <joint name="L_F23" type="fixed">
    <origin rpy="0 0 0" xyz="0 0 -0.024"/>
    <axis xyz="1 0 0"/>
    <parent link="L_F22_LINK"/>
    <child link="L_F23_LINK"/>
    <limit effort="1" lower="-1.22173045555556" upper="0" velocity="1"/>
    <mimic joint="L_HAND_J1" multiplier="1" offset="0"/>
  </joint>
  <joint name="L_F32" type="fixed">
    <origin rpy="0 0 0" xyz="0.0051 0 -0.045"/>
    <axis xyz="1 0 0"/>
    <parent link="L_HAND_J1_LINK"/>
    <child link="L_F32_LINK"/>
    <limit effort="1" lower="-1.22173045555556" upper="0" velocity="1"/>
    <mimic joint="L_HAND_J1" multiplier="1" offset="0"/>
  </joint>
  <joint name="L_F33" type="fixed">
    <origin rpy="0 0 0" xyz="0 0 -0.024"/>
    <axis xyz="1 0 0"/>
    <parent link="L_F32_LINK"/>
    <child link="L_F33_LINK"/>
    <limit effort="1" lower="-1.22173045555556" upper="0" velocity="1"/>
    <mimic joint="L_HAND_J1" multiplier="1" offset="0"/>
  </joint>
  <joint name="L_F42" type="fixed">
    <origin rpy="0 0 0" xyz="-0.0151 0 -0.045"/>
    <axis xyz="1 0 0"/>
    <parent link="L_HAND_J1_LINK"/>
    <child link="L_F42_LINK"/>
    <limit effort="1" lower="-1.22173045555556" upper="0" velocity="1"/>
    <mimic joint="L_HAND_J1" multiplier="1" offset="0"/>
  </joint>
  <joint name="L_F43" type="fixed">
    <origin rpy="0 0 0" xyz="0 0 -0.024"/>
    <axis xyz="1 0 0"/>
    <parent link="L_F42_LINK"/>
    <child link="L_F43_LINK"/>
    <limit effort="1" lower="-1.22173045555556" upper="0" velocity="1"/>
    <mimic joint="L_HAND_J1" multiplier="1" offset="0"/>
  </joint>
  <joint name="L_F52" type="fixed">
    <origin rpy="0 0 0" xyz="-0.0353 0 -0.045"/>
    <axis xyz="1 0 0"/>
    <parent link="L_HAND_J1_LINK"/>
    <child link="L_F52_LINK"/>
    <limit effort="1" lower="-1.22173045555556" upper="0" velocity="1"/>
    <mimic joint="L_HAND_J1" multiplier="1" offset="0"/>
  </joint>
  <joint name="L_F53" type="fixed">
    <origin rpy="0 0 0" xyz="0 0 -0.024"/>
    <axis xyz="1 0 0"/>
    <parent link="L_F52_LINK"/>
    <child link="L_F53_LINK"/>
    <limit effort="1" lower="-1.22173045555556" upper="0" velocity="1"/>
    <mimic joint="L_HAND_J1" multiplier="1" offset="0"/>
  </joint>
  <!-- right foot -->
  <joint name="R_FOOT" type="fixed">
    <origin rpy="0 0 0" xyz="0 0 0"/>
    <axis xyz="0 0 0"/>
    <parent link="R_ANKLE_R_LINK"/>
    <child link="r_ankle"/>
  </joint>
  <link name="r_ankle">
    <inertial>
      <origin rpy="0 0 0" xyz="0.01130279 -0.01139641 -0.07868422"/>
      <mass value="0.57831553"/>
      <inertia ixx="0.00121526" ixy="8.51e-06" ixz="2.787e-05" iyy="0.00254705" iyz="-2.1e-06" izz="0.00362666"/>
    </inertial>
    <visual>
      <origin rpy="0 0 0" xyz="0 0 0"/>
      <geometry>
        <mesh filename="./meshes/R_FOOT.dae"/>
      </geometry>
    </visual>
    <collision>
      <origin rpy="0 0 0" xyz="0 0 0"/>
      <geometry>
        <mesh filename="./meshes/R_FOOT.dae"/>
      </geometry>
    </collision>
  </link>
  <!-- left foot -->
  <joint name="L_FOOT" type="fixed">
    <origin rpy="0 0 0" xyz="0 0 0"/>
    <axis xyz="0 0 0"/>
    <parent link="L_ANKLE_R_LINK"/>
    <child link="l_ankle"/>
  </joint>
  <link name="l_ankle">
    <inertial>
      <origin rpy="0 0 0" xyz="0.01130279 0.01139641 -0.07868422"/>
      <mass value="0.57831553"/>
      <inertia ixx="0.00121526" ixy="-8.51e-06" ixz="2.787e-05" iyy="0.00254705" iyz="2.1e-06" izz="0.00362666"/>
    </inertial>
    <visual>
      <origin rpy="0 0 0" xyz="0 0 0"/>
      <geometry>
        <mesh filename="./meshes/L_FOOT.dae"/>
      </geometry>
    </visual>
    <collision>
      <origin rpy="0 0 0" xyz="0 0 0"/>
      <geometry>
        <mesh filename="./meshes/L_FOOT.dae"/>
      </geometry>
    </collision>
  </link>
</robot>
